{"created": 1753702827.3875139, "duration": 0.3697547912597656, "exitcode": 1, "root": "C:\\Users\\zak\\Desktop\\workspace\\git\\permiso_functional_tests", "environment": {}, "summary": {"failed": 7, "passed": 6, "skipped": 4, "total": 17, "collected": 17}, "collectors": [{"nodeid": "", "outcome": "passed", "result": [{"nodeid": "tests/test_authentication_flows.py", "type": "Module"}]}, {"nodeid": "tests/test_authentication_flows.py::TestAuthenticationFlows", "outcome": "passed", "result": [{"nodeid": "tests/test_authentication_flows.py::TestAuthenticationFlows::test_user_login_success", "type": "Function", "lineno": 20}, {"nodeid": "tests/test_authentication_flows.py::TestAuthenticationFlows::test_user_login_invalid_credentials", "type": "Function", "lineno": 40}, {"nodeid": "tests/test_authentication_flows.py::TestAuthenticationFlows::test_user_login_missing_fields", "type": "Function", "lineno": 58}, {"nodeid": "tests/test_authentication_flows.py::TestAuthenticationFlows::test_service_client_authentication_success", "type": "Function", "lineno": 80}, {"nodeid": "tests/test_authentication_flows.py::TestAuthenticationFlows::test_service_client_invalid_credentials", "type": "Function", "lineno": 99}, {"nodeid": "tests/test_authentication_flows.py::TestAuthenticationFlows::test_token_refresh_success", "type": "Function", "lineno": 117}, {"nodeid": "tests/test_authentication_flows.py::TestAuthenticationFlows::test_token_refresh_invalid_token", "type": "Function", "lineno": 151}, {"nodeid": "tests/test_authentication_flows.py::TestAuthenticationFlows::test_token_refresh_expired_token", "type": "Function", "lineno": 164}, {"nodeid": "tests/test_authentication_flows.py::TestAuthenticationFlows::test_authenticated_request_with_valid_token", "type": "Function", "lineno": 178}, {"nodeid": "tests/test_authentication_flows.py::TestAuthenticationFlows::test_authenticated_request_without_token", "type": "Function", "lineno": 189}, {"nodeid": "tests/test_authentication_flows.py::TestAuthenticationFlows::test_authenticated_request_with_invalid_token", "type": "Function", "lineno": 199}, {"nodeid": "tests/test_authentication_flows.py::TestAuthenticationFlows::test_logout_success", "type": "Function", "lineno": 213}, {"nodeid": "tests/test_authentication_flows.py::TestAuthenticationFlows::test_logout_without_authentication", "type": "Function", "lineno": 233}, {"nodeid": "tests/test_authentication_flows.py::TestAuthenticationFlows::test_multiple_login_sessions", "type": "Function", "lineno": 241}, {"nodeid": "tests/test_authentication_flows.py::TestAuthenticationFlows::test_token_introspection", "type": "Function", "lineno": 274}, {"nodeid": "tests/test_authentication_flows.py::TestAuthenticationFlows::test_token_revocation", "type": "Function", "lineno": 294}, {"nodeid": "tests/test_authentication_flows.py::TestAuthenticationFlows::test_complete_authentication_flow", "type": "Function", "lineno": 319}]}, {"nodeid": "tests/test_authentication_flows.py", "outcome": "passed", "result": [{"nodeid": "tests/test_authentication_flows.py::TestAuthenticationFlows", "type": "Class"}]}], "tests": [{"nodeid": "tests/test_authentication_flows.py::TestAuthenticationFlows::test_user_login_success", "lineno": 20, "outcome": "failed", "keywords": ["test_user_login_success", "TestAuthenticationFlows", "test_authentication_flows.py", "tests", "permiso_functional_tests", ""], "setup": {"duration": 0.03522040000098059, "outcome": "passed"}, "call": {"duration": 0.016973600000710576, "outcome": "failed", "crash": {"path": "C:\\Users\\zak\\Desktop\\workspace\\git\\permiso_functional_tests\\tests\\test_authentication_flows.py", "lineno": 31, "message": "AssertionError: Login failed: 422 - {\"error\": \"validation_error\", \"error_description\": \"Request validation failed\", \"details\": [{\"type\": \"missing\", \"loc\": [\"body\", \"username\"], \"msg\": \"Field required\", \"input\": null, \"url\": \"https://errors.pydantic.dev/2.11/v/missing\"}, {\"type\": \"missing\", \"loc\": [\"body\", \"password\"], \"msg\": \"Field required\", \"input\": null, \"url\": \"https://errors.pydantic.dev/2.11/v/missing\"}]}\nassert 422 == 200\n +  where 422 = <Response [422]>.status_code"}, "traceback": [{"path": "tests\\test_authentication_flows.py", "lineno": 31, "message": "AssertionError"}], "longrepr": "self = <tests.test_authentication_flows.TestAuthenticationFlows object at 0x0000016F63641DF0>, client = <tests.conftest.PermisoClient object at 0x0000016F6686C4A0>\n\n    def test_user_login_success(self, client):\n        \"\"\"Test successful user login with valid credentials.\"\"\"\n        data = {\n            \"username\": USER_USERNAME,\n            \"password\": USER_PASSWORD,\n            \"grant_type\": \"password\"\n        }\n    \n        response = client.post(\"/auth/token\", data=data)\n    \n>       assert response.status_code == 200, \\\n            f\"Login failed: {response.status_code} - {response.text}\"\nE       AssertionError: Login failed: 422 - {\"error\": \"validation_error\", \"error_description\": \"Request validation failed\", \"details\": [{\"type\": \"missing\", \"loc\": [\"body\", \"username\"], \"msg\": \"Field required\", \"input\": null, \"url\": \"https://errors.pydantic.dev/2.11/v/missing\"}, {\"type\": \"missing\", \"loc\": [\"body\", \"password\"], \"msg\": \"Field required\", \"input\": null, \"url\": \"https://errors.pydantic.dev/2.11/v/missing\"}]}\nE       assert 422 == 200\nE        +  where 422 = <Response [422]>.status_code\n\ntests\\test_authentication_flows.py:31: AssertionError"}, "teardown": {"duration": 0.0002382000002398854, "outcome": "passed"}}, {"nodeid": "tests/test_authentication_flows.py::TestAuthenticationFlows::test_user_login_invalid_credentials", "lineno": 40, "outcome": "failed", "keywords": ["test_user_login_invalid_credentials", "TestAuthenticationFlows", "test_authentication_flows.py", "tests", "permiso_functional_tests", ""], "setup": {"duration": 0.00021389999892562628, "outcome": "passed"}, "call": {"duration": 0.011709899999914342, "outcome": "failed", "crash": {"path": "C:\\Users\\zak\\Desktop\\workspace\\git\\permiso_functional_tests\\tests\\test_authentication_flows.py", "lineno": 51, "message": "AssertionError: Expected 401 for invalid credentials, got 422\nassert 422 == 401\n +  where 422 = <Response [422]>.status_code"}, "traceback": [{"path": "tests\\test_authentication_flows.py", "lineno": 51, "message": "AssertionError"}], "longrepr": "self = <tests.test_authentication_flows.TestAuthenticationFlows object at 0x0000016F66822AB0>, client = <tests.conftest.PermisoClient object at 0x0000016F6694C1D0>\n\n    def test_user_login_invalid_credentials(self, client):\n        \"\"\"Test login with invalid credentials returns proper error.\"\"\"\n        data = {\n            \"username\": \"invalid_user\",\n            \"password\": \"wrong_password\",\n            \"grant_type\": \"password\"\n        }\n    \n        response = client.post(\"/auth/token\", data=data)\n    \n>       assert response.status_code == 401, \\\n            f\"Expected 401 for invalid credentials, got {response.status_code}\"\nE       AssertionError: Expected 401 for invalid credentials, got 422\nE       assert 422 == 401\nE        +  where 422 = <Response [422]>.status_code\n\ntests\\test_authentication_flows.py:51: AssertionError"}, "teardown": {"duration": 0.00022149999858811498, "outcome": "passed"}}, {"nodeid": "tests/test_authentication_flows.py::TestAuthenticationFlows::test_user_login_missing_fields", "lineno": 58, "outcome": "passed", "keywords": ["test_user_login_missing_fields", "TestAuthenticationFlows", "test_authentication_flows.py", "tests", "permiso_functional_tests", ""], "setup": {"duration": 0.0002967000000353437, "outcome": "passed"}, "call": {"duration": 0.05792409999958181, "outcome": "passed"}, "teardown": {"duration": 0.00018530000124883372, "outcome": "passed"}}, {"nodeid": "tests/test_authentication_flows.py::TestAuthenticationFlows::test_service_client_authentication_success", "lineno": 80, "outcome": "failed", "keywords": ["test_service_client_authentication_success", "TestAuthenticationFlows", "test_authentication_flows.py", "tests", "permiso_functional_tests", ""], "setup": {"duration": 0.00024709999888727907, "outcome": "passed"}, "call": {"duration": 0.01097490000029211, "outcome": "failed", "crash": {"path": "C:\\Users\\zak\\Desktop\\workspace\\git\\permiso_functional_tests\\tests\\test_authentication_flows.py", "lineno": 91, "message": "AssertionError: Service client auth failed: 422 - {\"error\": \"validation_error\", \"error_description\": \"Request validation failed\", \"details\": [{\"type\": \"missing\", \"loc\": [\"body\", \"client_id\"], \"msg\": \"Field required\", \"input\": null, \"url\": \"https://errors.pydantic.dev/2.11/v/missing\"}, {\"type\": \"missing\", \"loc\": [\"body\", \"client_secret\"], \"msg\": \"Field required\", \"input\": null, \"url\": \"https://errors.pydantic.dev/2.11/v/missing\"}]}\nassert 422 == 200\n +  where 422 = <Response [422]>.status_code"}, "traceback": [{"path": "tests\\test_authentication_flows.py", "lineno": 91, "message": "AssertionError"}], "longrepr": "self = <tests.test_authentication_flows.TestAuthenticationFlows object at 0x0000016F66822F60>, client = <tests.conftest.PermisoClient object at 0x0000016F66892390>\n\n    def test_service_client_authentication_success(self, client):\n        \"\"\"Test successful service client authentication.\"\"\"\n        data = {\n            \"client_id\": CLIENT_ID,\n            \"client_secret\": CLIENT_SECRET,\n            \"grant_type\": \"client_credentials\"\n        }\n    \n        response = client.post(\"/auth/service-token\", data=data)\n    \n>       assert response.status_code == 200, \\\n            f\"Service client auth failed: {response.status_code} - {response.text}\"\nE       AssertionError: Service client auth failed: 422 - {\"error\": \"validation_error\", \"error_description\": \"Request validation failed\", \"details\": [{\"type\": \"missing\", \"loc\": [\"body\", \"client_id\"], \"msg\": \"Field required\", \"input\": null, \"url\": \"https://errors.pydantic.dev/2.11/v/missing\"}, {\"type\": \"missing\", \"loc\": [\"body\", \"client_secret\"], \"msg\": \"Field required\", \"input\": null, \"url\": \"https://errors.pydantic.dev/2.11/v/missing\"}]}\nE       assert 422 == 200\nE        +  where 422 = <Response [422]>.status_code\n\ntests\\test_authentication_flows.py:91: AssertionError"}, "teardown": {"duration": 0.000424000001657987, "outcome": "passed"}}, {"nodeid": "tests/test_authentication_flows.py::TestAuthenticationFlows::test_service_client_invalid_credentials", "lineno": 99, "outcome": "failed", "keywords": ["test_service_client_invalid_credentials", "TestAuthenticationFlows", "test_authentication_flows.py", "tests", "permiso_functional_tests", ""], "setup": {"duration": 0.0002674000006663846, "outcome": "passed"}, "call": {"duration": 0.011017300001185504, "outcome": "failed", "crash": {"path": "C:\\Users\\zak\\Desktop\\workspace\\git\\permiso_functional_tests\\tests\\test_authentication_flows.py", "lineno": 110, "message": "AssertionError: Expected 401 for invalid client credentials, got 422\nassert 422 == 401\n +  where 422 = <Response [422]>.status_code"}, "traceback": [{"path": "tests\\test_authentication_flows.py", "lineno": 110, "message": "AssertionError"}], "longrepr": "self = <tests.test_authentication_flows.TestAuthenticationFlows object at 0x0000016F668230E0>, client = <tests.conftest.PermisoClient object at 0x0000016F6694FC80>\n\n    def test_service_client_invalid_credentials(self, client):\n        \"\"\"Test service client authentication with invalid credentials.\"\"\"\n        data = {\n            \"client_id\": \"invalid_client\",\n            \"client_secret\": \"invalid_secret\",\n            \"grant_type\": \"client_credentials\"\n        }\n    \n        response = client.post(\"/auth/service-token\", data=data)\n    \n>       assert response.status_code == 401, \\\n            f\"Expected 401 for invalid client credentials, got {response.status_code}\"\nE       AssertionError: Expected 401 for invalid client credentials, got 422\nE       assert 422 == 401\nE        +  where 422 = <Response [422]>.status_code\n\ntests\\test_authentication_flows.py:110: AssertionError"}, "teardown": {"duration": 0.00031380000109493267, "outcome": "passed"}}, {"nodeid": "tests/test_authentication_flows.py::TestAuthenticationFlows::test_token_refresh_success", "lineno": 117, "outcome": "failed", "keywords": ["test_token_refresh_success", "TestAuthenticationFlows", "test_authentication_flows.py", "tests", "permiso_functional_tests", ""], "setup": {"duration": 0.00025040000036824495, "outcome": "passed"}, "call": {"duration": 0.011547100000825594, "outcome": "failed", "crash": {"path": "C:\\Users\\zak\\Desktop\\workspace\\git\\permiso_functional_tests\\tests\\test_authentication_flows.py", "lineno": 122, "message": "AssertionError: Initial login failed\nassert False"}, "traceback": [{"path": "tests\\test_authentication_flows.py", "lineno": 122, "message": "AssertionError"}], "longrepr": "self = <tests.test_authentication_flows.TestAuthenticationFlows object at 0x0000016F66823260>, client = <tests.conftest.PermisoClient object at 0x0000016F6694F6E0>\n\n    def test_token_refresh_success(self, client):\n        \"\"\"Test successful token refresh.\"\"\"\n        # First login to get tokens\n        success = client.login_user(USER_USERNAME, USER_PASSWORD)\n>       assert success, \"Initial login failed\"\nE       AssertionError: Initial login failed\nE       assert False\n\ntests\\test_authentication_flows.py:122: AssertionError"}, "teardown": {"duration": 0.00025720000121509656, "outcome": "passed"}}, {"nodeid": "tests/test_authentication_flows.py::TestAuthenticationFlows::test_token_refresh_invalid_token", "lineno": 151, "outcome": "passed", "keywords": ["test_token_refresh_invalid_token", "TestAuthenticationFlows", "test_authentication_flows.py", "tests", "permiso_functional_tests", ""], "setup": {"duration": 0.00026789999901666306, "outcome": "passed"}, "call": {"duration": 0.011170300000230782, "outcome": "passed"}, "teardown": {"duration": 0.00013800000124319922, "outcome": "passed"}}, {"nodeid": "tests/test_authentication_flows.py::TestAuthenticationFlows::test_token_refresh_expired_token", "lineno": 164, "outcome": "passed", "keywords": ["test_token_refresh_expired_token", "TestAuthenticationFlows", "test_authentication_flows.py", "tests", "permiso_functional_tests", ""], "setup": {"duration": 0.0002280000007885974, "outcome": "passed"}, "call": {"duration": 0.011120699999082717, "outcome": "passed"}, "teardown": {"duration": 0.00014270000065153, "outcome": "passed"}}, {"nodeid": "tests/test_authentication_flows.py::TestAuthenticationFlows::test_authenticated_request_with_valid_token", "lineno": 178, "outcome": "skipped", "keywords": ["test_authenticated_request_with_valid_token", "TestAuthenticationFlows", "test_authentication_flows.py", "tests", "permiso_functional_tests", ""], "setup": {"duration": 0.01163510000151291, "outcome": "skipped", "longrepr": "('C:\\\\Users\\\\zak\\\\Desktop\\\\workspace\\\\git\\\\permiso_functional_tests\\\\tests\\\\test_authentication_flows.py', 179, 'Skipped: Failed to authenticate regular user')"}, "teardown": {"duration": 0.0001551000004837988, "outcome": "passed"}}, {"nodeid": "tests/test_authentication_flows.py::TestAuthenticationFlows::test_authenticated_request_without_token", "lineno": 189, "outcome": "passed", "keywords": ["test_authenticated_request_without_token", "TestAuthenticationFlows", "test_authentication_flows.py", "tests", "permiso_functional_tests", ""], "setup": {"duration": 0.00020820000099774916, "outcome": "passed"}, "call": {"duration": 0.011212400000658818, "outcome": "passed"}, "teardown": {"duration": 0.00042380000013508834, "outcome": "passed"}}, {"nodeid": "tests/test_authentication_flows.py::TestAuthenticationFlows::test_authenticated_request_with_invalid_token", "lineno": 199, "outcome": "passed", "keywords": ["test_authenticated_request_with_invalid_token", "TestAuthenticationFlows", "test_authentication_flows.py", "tests", "permiso_functional_tests", ""], "setup": {"duration": 0.00029240000003483146, "outcome": "passed"}, "call": {"duration": 0.011011500000677188, "outcome": "passed"}, "teardown": {"duration": 0.0001322999996773433, "outcome": "passed"}}, {"nodeid": "tests/test_authentication_flows.py::TestAuthenticationFlows::test_logout_success", "lineno": 213, "outcome": "skipped", "keywords": ["test_logout_success", "TestAuthenticationFlows", "test_authentication_flows.py", "tests", "permiso_functional_tests", ""], "setup": {"duration": 0.01156020000053104, "outcome": "skipped", "longrepr": "('C:\\\\Users\\\\zak\\\\Desktop\\\\workspace\\\\git\\\\permiso_functional_tests\\\\tests\\\\test_authentication_flows.py', 214, 'Skipped: Failed to authenticate regular user')"}, "teardown": {"duration": 0.00017380000099365134, "outcome": "passed"}}, {"nodeid": "tests/test_authentication_flows.py::TestAuthenticationFlows::test_logout_without_authentication", "lineno": 233, "outcome": "passed", "keywords": ["test_logout_without_authentication", "TestAuthenticationFlows", "test_authentication_flows.py", "tests", "permiso_functional_tests", ""], "setup": {"duration": 0.00023040000087348744, "outcome": "passed"}, "call": {"duration": 0.011624400000073365, "outcome": "passed"}, "teardown": {"duration": 0.00014100000043981709, "outcome": "passed"}}, {"nodeid": "tests/test_authentication_flows.py::TestAuthenticationFlows::test_multiple_login_sessions", "lineno": 241, "outcome": "failed", "keywords": ["test_multiple_login_sessions", "TestAuthenticationFlows", "test_authentication_flows.py", "tests", "permiso_functional_tests", ""], "setup": {"duration": 0.00025629999981902074, "outcome": "passed"}, "call": {"duration": 0.010845400000107475, "outcome": "failed", "crash": {"path": "C:\\Users\\zak\\Desktop\\workspace\\git\\permiso_functional_tests\\tests\\test_authentication_flows.py", "lineno": 247, "message": "AssertionError: First login failed\nassert False"}, "traceback": [{"path": "tests\\test_authentication_flows.py", "lineno": 247, "message": "AssertionError"}], "longrepr": "self = <tests.test_authentication_flows.TestAuthenticationFlows object at 0x0000016F66823B30>, client = <tests.conftest.PermisoClient object at 0x0000016F66989D90>\n\n    def test_multiple_login_sessions(self, client):\n        \"\"\"Test that multiple login sessions can coexist.\"\"\"\n        # Create first session\n        client1 = PermisoClient()\n        success1 = client1.login_user(USER_USERNAME, USER_PASSWORD)\n>       assert success1, \"First login failed\"\nE       AssertionError: First login failed\nE       assert False\n\ntests\\test_authentication_flows.py:247: AssertionError"}, "teardown": {"duration": 0.00019939999947382603, "outcome": "passed"}}, {"nodeid": "tests/test_authentication_flows.py::TestAuthenticationFlows::test_token_introspection", "lineno": 274, "outcome": "skipped", "keywords": ["test_token_introspection", "TestAuthenticationFlows", "test_authentication_flows.py", "tests", "permiso_functional_tests", ""], "setup": {"duration": 0.011593799999900511, "outcome": "skipped", "longrepr": "('C:\\\\Users\\\\zak\\\\Desktop\\\\workspace\\\\git\\\\permiso_functional_tests\\\\tests\\\\test_authentication_flows.py', 275, 'Skipped: Failed to authenticate admin user')"}, "teardown": {"duration": 0.0002041000007011462, "outcome": "passed"}}, {"nodeid": "tests/test_authentication_flows.py::TestAuthenticationFlows::test_token_revocation", "lineno": 294, "outcome": "skipped", "keywords": ["test_token_revocation", "TestAuthenticationFlows", "test_authentication_flows.py", "tests", "permiso_functional_tests", ""], "setup": {"duration": 0.01013039999998, "outcome": "skipped", "longrepr": "('C:\\\\Users\\\\zak\\\\Desktop\\\\workspace\\\\git\\\\permiso_functional_tests\\\\tests\\\\test_authentication_flows.py', 295, 'Skipped: Failed to authenticate admin user')"}, "teardown": {"duration": 0.00013489999946614262, "outcome": "passed"}}, {"nodeid": "tests/test_authentication_flows.py::TestAuthenticationFlows::test_complete_authentication_flow", "lineno": 319, "outcome": "failed", "keywords": ["test_complete_authentication_flow", "TestAuthenticationFlows", "test_authentication_flows.py", "tests", "permiso_functional_tests", ""], "setup": {"duration": 0.00022780000108468812, "outcome": "passed"}, "call": {"duration": 0.011198100000910927, "outcome": "failed", "crash": {"path": "C:\\Users\\zak\\Desktop\\workspace\\git\\permiso_functional_tests\\tests\\test_authentication_flows.py", "lineno": 324, "message": "AssertionError: Login failed\nassert False"}, "traceback": [{"path": "tests\\test_authentication_flows.py", "lineno": 324, "message": "AssertionError"}], "longrepr": "self = <tests.test_authentication_flows.TestAuthenticationFlows object at 0x0000016F6686C110>, client = <tests.conftest.PermisoClient object at 0x0000016F66972CC0>\n\n    def test_complete_authentication_flow(self, client):\n        \"\"\"Test complete authentication flow from login to logout.\"\"\"\n        # Step 1: Login\n        success = client.login_user(USER_USERNAME, USER_PASSWORD)\n>       assert success, \"Login failed\"\nE       AssertionError: Login failed\nE       assert False\n\ntests\\test_authentication_flows.py:324: AssertionError"}, "teardown": {"duration": 0.00022189999981492292, "outcome": "passed"}}], "warnings": [{"message": "Unverified HTTPS request is being made to host 'localhost'. Adding certificate verification is strongly advised. See: https://urllib3.readthedocs.io/en/latest/advanced-usage.html#tls-warnings", "category": "InsecureRequestWarning", "when": "runtest", "filename": "C:\\Users\\zak\\Desktop\\workspace\\git\\permiso_functional_tests\\.venv\\Lib\\site-packages\\urllib3\\connectionpool.py", "lineno": 1097}, {"message": "Unverified HTTPS request is being made to host 'localhost'. Adding certificate verification is strongly advised. See: https://urllib3.readthedocs.io/en/latest/advanced-usage.html#tls-warnings", "category": "InsecureRequestWarning", "when": "runtest", "filename": "C:\\Users\\zak\\Desktop\\workspace\\git\\permiso_functional_tests\\.venv\\Lib\\site-packages\\urllib3\\connectionpool.py", "lineno": 1097}, {"message": "Unverified HTTPS request is being made to host 'localhost'. Adding certificate verification is strongly advised. See: https://urllib3.readthedocs.io/en/latest/advanced-usage.html#tls-warnings", "category": "InsecureRequestWarning", "when": "runtest", "filename": "C:\\Users\\zak\\Desktop\\workspace\\git\\permiso_functional_tests\\.venv\\Lib\\site-packages\\urllib3\\connectionpool.py", "lineno": 1097}, {"message": "Unverified HTTPS request is being made to host 'localhost'. Adding certificate verification is strongly advised. See: https://urllib3.readthedocs.io/en/latest/advanced-usage.html#tls-warnings", "category": "InsecureRequestWarning", "when": "runtest", "filename": "C:\\Users\\zak\\Desktop\\workspace\\git\\permiso_functional_tests\\.venv\\Lib\\site-packages\\urllib3\\connectionpool.py", "lineno": 1097}, {"message": "Unverified HTTPS request is being made to host 'localhost'. Adding certificate verification is strongly advised. See: https://urllib3.readthedocs.io/en/latest/advanced-usage.html#tls-warnings", "category": "InsecureRequestWarning", "when": "runtest", "filename": "C:\\Users\\zak\\Desktop\\workspace\\git\\permiso_functional_tests\\.venv\\Lib\\site-packages\\urllib3\\connectionpool.py", "lineno": 1097}, {"message": "Unverified HTTPS request is being made to host 'localhost'. Adding certificate verification is strongly advised. See: https://urllib3.readthedocs.io/en/latest/advanced-usage.html#tls-warnings", "category": "InsecureRequestWarning", "when": "runtest", "filename": "C:\\Users\\zak\\Desktop\\workspace\\git\\permiso_functional_tests\\.venv\\Lib\\site-packages\\urllib3\\connectionpool.py", "lineno": 1097}, {"message": "Unverified HTTPS request is being made to host 'localhost'. Adding certificate verification is strongly advised. See: https://urllib3.readthedocs.io/en/latest/advanced-usage.html#tls-warnings", "category": "InsecureRequestWarning", "when": "runtest", "filename": "C:\\Users\\zak\\Desktop\\workspace\\git\\permiso_functional_tests\\.venv\\Lib\\site-packages\\urllib3\\connectionpool.py", "lineno": 1097}, {"message": "Unverified HTTPS request is being made to host 'localhost'. Adding certificate verification is strongly advised. See: https://urllib3.readthedocs.io/en/latest/advanced-usage.html#tls-warnings", "category": "InsecureRequestWarning", "when": "runtest", "filename": "C:\\Users\\zak\\Desktop\\workspace\\git\\permiso_functional_tests\\.venv\\Lib\\site-packages\\urllib3\\connectionpool.py", "lineno": 1097}, {"message": "Unverified HTTPS request is being made to host 'localhost'. Adding certificate verification is strongly advised. See: https://urllib3.readthedocs.io/en/latest/advanced-usage.html#tls-warnings", "category": "InsecureRequestWarning", "when": "runtest", "filename": "C:\\Users\\zak\\Desktop\\workspace\\git\\permiso_functional_tests\\.venv\\Lib\\site-packages\\urllib3\\connectionpool.py", "lineno": 1097}, {"message": "Unverified HTTPS request is being made to host 'localhost'. Adding certificate verification is strongly advised. See: https://urllib3.readthedocs.io/en/latest/advanced-usage.html#tls-warnings", "category": "InsecureRequestWarning", "when": "runtest", "filename": "C:\\Users\\zak\\Desktop\\workspace\\git\\permiso_functional_tests\\.venv\\Lib\\site-packages\\urllib3\\connectionpool.py", "lineno": 1097}, {"message": "Unverified HTTPS request is being made to host 'localhost'. Adding certificate verification is strongly advised. See: https://urllib3.readthedocs.io/en/latest/advanced-usage.html#tls-warnings", "category": "InsecureRequestWarning", "when": "runtest", "filename": "C:\\Users\\zak\\Desktop\\workspace\\git\\permiso_functional_tests\\.venv\\Lib\\site-packages\\urllib3\\connectionpool.py", "lineno": 1097}, {"message": "Unverified HTTPS request is being made to host 'localhost'. Adding certificate verification is strongly advised. See: https://urllib3.readthedocs.io/en/latest/advanced-usage.html#tls-warnings", "category": "InsecureRequestWarning", "when": "runtest", "filename": "C:\\Users\\zak\\Desktop\\workspace\\git\\permiso_functional_tests\\.venv\\Lib\\site-packages\\urllib3\\connectionpool.py", "lineno": 1097}, {"message": "Unverified HTTPS request is being made to host 'localhost'. Adding certificate verification is strongly advised. See: https://urllib3.readthedocs.io/en/latest/advanced-usage.html#tls-warnings", "category": "InsecureRequestWarning", "when": "runtest", "filename": "C:\\Users\\zak\\Desktop\\workspace\\git\\permiso_functional_tests\\.venv\\Lib\\site-packages\\urllib3\\connectionpool.py", "lineno": 1097}, {"message": "Unverified HTTPS request is being made to host 'localhost'. Adding certificate verification is strongly advised. See: https://urllib3.readthedocs.io/en/latest/advanced-usage.html#tls-warnings", "category": "InsecureRequestWarning", "when": "runtest", "filename": "C:\\Users\\zak\\Desktop\\workspace\\git\\permiso_functional_tests\\.venv\\Lib\\site-packages\\urllib3\\connectionpool.py", "lineno": 1097}, {"message": "Unverified HTTPS request is being made to host 'localhost'. Adding certificate verification is strongly advised. See: https://urllib3.readthedocs.io/en/latest/advanced-usage.html#tls-warnings", "category": "InsecureRequestWarning", "when": "runtest", "filename": "C:\\Users\\zak\\Desktop\\workspace\\git\\permiso_functional_tests\\.venv\\Lib\\site-packages\\urllib3\\connectionpool.py", "lineno": 1097}, {"message": "Unverified HTTPS request is being made to host 'localhost'. Adding certificate verification is strongly advised. See: https://urllib3.readthedocs.io/en/latest/advanced-usage.html#tls-warnings", "category": "InsecureRequestWarning", "when": "runtest", "filename": "C:\\Users\\zak\\Desktop\\workspace\\git\\permiso_functional_tests\\.venv\\Lib\\site-packages\\urllib3\\connectionpool.py", "lineno": 1097}, {"message": "Unverified HTTPS request is being made to host 'localhost'. Adding certificate verification is strongly advised. See: https://urllib3.readthedocs.io/en/latest/advanced-usage.html#tls-warnings", "category": "InsecureRequestWarning", "when": "runtest", "filename": "C:\\Users\\zak\\Desktop\\workspace\\git\\permiso_functional_tests\\.venv\\Lib\\site-packages\\urllib3\\connectionpool.py", "lineno": 1097}]}